<?xml version="1.0" encoding="UTF-8"?>
<testng-results skipped="0" failed="2" ignored="0" total="3" passed="1">
  <reporter-output>
  </reporter-output>
  <suite name="Default suite" duration-ms="31298" started-at="2017-08-17T06:07:02Z" finished-at="2017-08-17T06:07:33Z">
    <groups>
    </groups>
    <test name="Default test" duration-ms="31298" started-at="2017-08-17T06:07:02Z" finished-at="2017-08-17T06:07:33Z">
      <class name="sa.dataDriven.AdactinLoginMultipleTest">
        <test-method status="PASS" signature="beforeClass()[pri:0, instance:sa.dataDriven.AdactinLoginMultipleTest@9629756]" name="beforeClass" is-config="true" duration-ms="5038" started-at="2017-08-17T11:37:02Z" finished-at="2017-08-17T11:37:07Z">
          <reporter-output>
          </reporter-output>
        </test-method> <!-- beforeClass -->
        <test-method status="FAIL" signature="main(java.lang.String, java.lang.String)[pri:0, instance:sa.dataDriven.AdactinLoginMultipleTest@9629756]" name="main" duration-ms="12996" started-at="2017-08-17T11:37:07Z" data-provider="loginData" finished-at="2017-08-17T11:37:20Z">
          <params>
            <param index="0">
              <value>
                <![CDATA[sanjay31786]]>
              </value>
            </param>
            <param index="1">
              <value>
                <![CDATA[mandal2]]>
              </value>
            </param>
          </params>
          <exception class="java.lang.AssertionError">
            <message>
              <![CDATA[expected [true] but found [false]]]>
            </message>
            <full-stacktrace>
              <![CDATA[java.lang.AssertionError: expected [true] but found [false]
	at org.testng.Assert.fail(Assert.java:93)
	at org.testng.Assert.failNotEquals(Assert.java:512)
	at org.testng.Assert.assertTrue(Assert.java:41)
	at org.testng.Assert.assertTrue(Assert.java:51)
	at sa.dataDriven.AdactinLoginMultipleTest.main(AdactinLoginMultipleTest.java:41)
	at sun.reflect.NativeMethodAccessorImpl.invoke0(Native Method)
	at sun.reflect.NativeMethodAccessorImpl.invoke(Unknown Source)
	at sun.reflect.DelegatingMethodAccessorImpl.invoke(Unknown Source)
	at java.lang.reflect.Method.invoke(Unknown Source)
	at org.testng.internal.MethodInvocationHelper.invokeMethod(MethodInvocationHelper.java:108)
	at org.testng.internal.Invoker.invokeMethod(Invoker.java:661)
	at org.testng.internal.Invoker.invokeTestMethod(Invoker.java:869)
	at org.testng.internal.Invoker.invokeTestMethods(Invoker.java:1193)
	at org.testng.internal.TestMethodWorker.invokeTestMethods(TestMethodWorker.java:126)
	at org.testng.internal.TestMethodWorker.run(TestMethodWorker.java:109)
	at org.testng.TestRunner.privateRun(TestRunner.java:744)
	at org.testng.TestRunner.run(TestRunner.java:602)
	at org.testng.SuiteRunner.runTest(SuiteRunner.java:380)
	at org.testng.SuiteRunner.runSequentially(SuiteRunner.java:375)
	at org.testng.SuiteRunner.privateRun(SuiteRunner.java:340)
	at org.testng.SuiteRunner.run(SuiteRunner.java:289)
	at org.testng.SuiteRunnerWorker.runSuite(SuiteRunnerWorker.java:52)
	at org.testng.SuiteRunnerWorker.run(SuiteRunnerWorker.java:86)
	at org.testng.TestNG.runSuitesSequentially(TestNG.java:1301)
	at org.testng.TestNG.runSuitesLocally(TestNG.java:1226)
	at org.testng.TestNG.runSuites(TestNG.java:1144)
	at org.testng.TestNG.run(TestNG.java:1115)
	at org.testng.remote.AbstractRemoteTestNG.run(AbstractRemoteTestNG.java:132)
	at org.testng.remote.RemoteTestNG.initAndRun(RemoteTestNG.java:230)
	at org.testng.remote.RemoteTestNG.main(RemoteTestNG.java:76)
]]>
            </full-stacktrace>
          </exception> <!-- java.lang.AssertionError -->
          <reporter-output>
          </reporter-output>
        </test-method> <!-- main -->
        <test-method status="FAIL" signature="main(java.lang.String, java.lang.String)[pri:0, instance:sa.dataDriven.AdactinLoginMultipleTest@9629756]" name="main" duration-ms="10961" started-at="2017-08-17T11:37:20Z" data-provider="loginData" finished-at="2017-08-17T11:37:31Z">
          <params>
            <param index="0">
              <value>
                <![CDATA[sanjay31999]]>
              </value>
            </param>
            <param index="1">
              <value>
                <![CDATA[madanl]]>
              </value>
            </param>
          </params>
          <exception class="java.lang.AssertionError">
            <message>
              <![CDATA[expected [true] but found [false]]]>
            </message>
            <full-stacktrace>
              <![CDATA[java.lang.AssertionError: expected [true] but found [false]
	at org.testng.Assert.fail(Assert.java:93)
	at org.testng.Assert.failNotEquals(Assert.java:512)
	at org.testng.Assert.assertTrue(Assert.java:41)
	at org.testng.Assert.assertTrue(Assert.java:51)
	at sa.dataDriven.AdactinLoginMultipleTest.main(AdactinLoginMultipleTest.java:41)
	at sun.reflect.NativeMethodAccessorImpl.invoke0(Native Method)
	at sun.reflect.NativeMethodAccessorImpl.invoke(Unknown Source)
	at sun.reflect.DelegatingMethodAccessorImpl.invoke(Unknown Source)
	at java.lang.reflect.Method.invoke(Unknown Source)
	at org.testng.internal.MethodInvocationHelper.invokeMethod(MethodInvocationHelper.java:108)
	at org.testng.internal.Invoker.invokeMethod(Invoker.java:661)
	at org.testng.internal.Invoker.invokeTestMethod(Invoker.java:869)
	at org.testng.internal.Invoker.invokeTestMethods(Invoker.java:1193)
	at org.testng.internal.TestMethodWorker.invokeTestMethods(TestMethodWorker.java:126)
	at org.testng.internal.TestMethodWorker.run(TestMethodWorker.java:109)
	at org.testng.TestRunner.privateRun(TestRunner.java:744)
	at org.testng.TestRunner.run(TestRunner.java:602)
	at org.testng.SuiteRunner.runTest(SuiteRunner.java:380)
	at org.testng.SuiteRunner.runSequentially(SuiteRunner.java:375)
	at org.testng.SuiteRunner.privateRun(SuiteRunner.java:340)
	at org.testng.SuiteRunner.run(SuiteRunner.java:289)
	at org.testng.SuiteRunnerWorker.runSuite(SuiteRunnerWorker.java:52)
	at org.testng.SuiteRunnerWorker.run(SuiteRunnerWorker.java:86)
	at org.testng.TestNG.runSuitesSequentially(TestNG.java:1301)
	at org.testng.TestNG.runSuitesLocally(TestNG.java:1226)
	at org.testng.TestNG.runSuites(TestNG.java:1144)
	at org.testng.TestNG.run(TestNG.java:1115)
	at org.testng.remote.AbstractRemoteTestNG.run(AbstractRemoteTestNG.java:132)
	at org.testng.remote.RemoteTestNG.initAndRun(RemoteTestNG.java:230)
	at org.testng.remote.RemoteTestNG.main(RemoteTestNG.java:76)
]]>
            </full-stacktrace>
          </exception> <!-- java.lang.AssertionError -->
          <reporter-output>
          </reporter-output>
        </test-method> <!-- main -->
        <test-method status="PASS" signature="main(java.lang.String, java.lang.String)[pri:0, instance:sa.dataDriven.AdactinLoginMultipleTest@9629756]" name="main" duration-ms="2285" started-at="2017-08-17T11:37:31Z" data-provider="loginData" finished-at="2017-08-17T11:37:33Z">
          <params>
            <param index="0">
              <value>
                <![CDATA[sanjay31786]]>
              </value>
            </param>
            <param index="1">
              <value>
                <![CDATA[mandal]]>
              </value>
            </param>
          </params>
          <reporter-output>
          </reporter-output>
        </test-method> <!-- main -->
      </class> <!-- sa.dataDriven.AdactinLoginMultipleTest -->
    </test> <!-- Default test -->
  </suite> <!-- Default suite -->
</testng-results>
